"""
Error handling utilities for VT application.

Provides standardized error handling and user feedback for various exception types.
"""

import asyncio
import contextlib
from typing import Any, Callable, Optional

import chainlit as cl
from litellm.exceptions import BadRequestError, RateLimitError, ServiceUnavailableError
from utils.config import logger


async def handle_exception(e: Exception) -> None:
    """
    Handles exceptions that occur during LLM interactions with specific error messages
    based on the type of exception.

    Args:
        e: The exception that was raised
    """
    error_message = "Something went wrong. "

    if isinstance(e, RateLimitError):
        error_message += "Rate limit exceeded. Please try again in a few moments."
    elif isinstance(e, BadRequestError):
        error_message += (
            "Invalid request parameters. Please check your inputs and try again."
        )
    elif isinstance(e, ServiceUnavailableError):
        error_message += (
            "The service is temporarily unavailable. Please try again later."
        )
    elif isinstance(e, ValueError):
        error_message += f"Invalid value: {str(e)}"
    elif isinstance(e, TimeoutError):
        error_message += "The request timed out. Please try again."
    else:
        error_message += f"Unexpected error: {str(e)}"

    logger.error("Error details: %s: %s", type(e).__name__, str(e))

    await cl.Message(content=error_message).send()


@contextlib.asynccontextmanager
async def safe_execution(
    operation_name: str,
    timeout_message: str = "The operation timed out. Please try again with a simpler query.",
    cancelled_message: str = "The operation was cancelled. Please try again.",
    on_timeout: Optional[Callable] = None,
    on_cancel: Optional[Callable] = None,
):
    """
    Context manager for safely executing asynchronous operations with standardized error handling.

    Args:
        operation_name: Name of the operation for logging purposes
        timeout_message: Message to display on timeout
        cancelled_message: Message to display when operation is cancelled
        on_timeout: Optional function to call on timeout
        on_cancel: Optional function to call when cancelled

    Yields:
        None
    """
    try:
        yield
    except asyncio.TimeoutError:
        logger.error(f"Timeout occurred during {operation_name}")
        if on_timeout:
            await on_timeout()
        else:
            await cl.Message(content=timeout_message).send()
    except asyncio.CancelledError:
        logger.warning(f"{operation_name} was cancelled")
        if on_cancel:
            await on_cancel()
        else:
            await cl.Message(content=cancelled_message).send()
        raise
    except Exception as e:
        logger.error(f"Error in {operation_name}: {e}")
        await handle_exception(e)
